Workbook

Sheet Cover
B2: FUNGI LABS MULTI-SPECIALITY HOSPITAL
B3: 100-Bed Greenfield Project | Nashik, Maharashtra | Tier-2 India
B5: MASTER FINANCIAL MODEL
B6: Feasibility · DPR · Financial Projections · Viability & Bankability
B8: Project | C8: Fungi Labs Multi-Speciality Hospital Pvt. Ltd.
B9: Facility | C9: 100 operational beds, balanced multi-specialty
B10: Location | C10: Nashik, Maharashtra (Tier-2), catchment ~21 lakh
B11: Land & building | C11: Greenfield — 2.0 acres freehold, 1,05,000 sq ft built-up
B12: Specialties | C12: Gen. Medicine · Gen. Surgery · Orthopaedics · Cardiology (cath lab) ·
C13: OBG · Paediatrics & NICU · Nephrology & Dialysis · Critical Care
B14: Project cost | C14: Rs 110.78 Cr (Rs 11,078 Lakh)
B15: Cost per bed | C15: Rs 1.11 Cr
B16: Funding — base case | C16: 70:30 Debt:Equity — Term loan Rs 77.54 Cr / Promoter equity Rs 33.23 Cr
B17: Promoter support facility | C17: Rs 17.80 Cr (DSRA + start-up deficit funding)
B18: Model horizon | C18: 10 operating years — FY2029 to FY2038
B19: Currency & units | C19: Indian Rupees. All amounts in Rs Lakh unless stated. 100 Lakh = 1 Crore.
B20: Model date | C20: 8 August 2026
B22: HEADLINE OUTPUTS — BASE CASE
B23: Revenue — Year 1 / Year 5 / Year 10 | C23: Rs 30.1 Cr / Rs 104.4 Cr / Rs 158.3 Cr
B24: EBITDA — Year 5 / Year 10 | C24: Rs 24.8 Cr (23.7%) / Rs 42.1 Cr (26.6%)
B25: EBITDA breakeven / PAT breakeven | C25: Year 2 / Year 4
B26: Minimum / Average DSCR (post-moratorium) | C26: 1.46x / 1.66x — covenant breaches: 0
B27: Project IRR / NPV @ 12.5% WACC | C27: 22.13% / Rs 123.2 Cr
B28: Equity IRR / Money multiple (10-yr hold) | C28: 26.91% / 12.32x
B29: Break-even occupancy (Year 5) — accounting / cash | C29: 45.2% / 61.1%
B32: COLOUR CONVENTION
B33: Blue text on yellow fill | C33: Hardcoded input or scenario lever — EDIT THESE
B34: Black text | C34: Formula calculated on this sheet — do not overwrite
B35: Green text | C35: Link to another sheet — do not overwrite
B37: SHEET INDEX
B38: Control Panel | C38: Scenario, funding-structure and payer-mix switches. START HERE.
B39: Assumptions | C39: Every operating, cost, working-capital, tax and valuation assumption
B40: Capex & Funding | C40: Cost of project, IDC closed-form solution, means of finance
B41: Depreciation | C41: Block-wise book depreciation (SLM) and income-tax WDV depreciation
B42: Revenue Build | C42: Bed-days, ARPOB, IPD/OPD/diagnostics/pharmacy/dialysis build-up
B43: Manpower | C43: Cadre-wise headcount and cost ramp
B44: Operating Costs | C44: Full opex build; variable vs fixed classification
B45: Working Capital | C45: Debtor days driven by payer mix; inventory, creditors, net WC
B46: Repayment Schedule | C46: Quarterly term-loan repayment ladder — 28 instalments
B47: Debt Schedule | C47: Annual term loan + working-capital facility, interest, closing balance
...

Sheet Control Panel
A1: CONTROL PANEL — MODEL SWITCHES
A2: Change the three switches below and the whole workbook recalculates. Edit ONLY the blue cells on yellow fill.
A5: Scenario (1 = Base, 2 = Optimistic, 3 = Pessimistic, 4 = Lender Stress) | B5: 1
A6: Active scenario | B6: =INDEX($C$16:$F$16,1,$B$5) -> Base
A8: Funding structure (1 = 70:30, 2 = 65:35, 3 = 60:40 with PE) | B8: 1
A9: Active funding structure | B9: =INDEX($C$32:$E$32,1,$B$8) -> Opt 1: 70:30
A11: Payer mix (1 = Blended, 2 = Government-heavy, 3 = Cash-premium) | B11: 1
A12: Active payer mix | B12: =INDEX($B$40:$D$40,1,$B$11) -> Blended
A15: SCENARIO DRIVER TABLE
A16: Driver | B16: Unit | C16: Base | D16: Optimistic | E16: Pessimistic | F16: Lender Stress | G16: ACTIVE
A17: Peak occupancy (stabilised) | B17: % | C17: 0.72 | D17: 0.78 | E17: 0.64 | F17: 0.58 | G17: =INDEX($C17:$F17,1,$B$5) -> 0.72 | I17: ICRA: sector 62-64%; well-run tier-2 65-75%
A18: Occupancy ramp multiplier | B18: x | C18: 1 | D18: 1.1 | E18: 0.88 | F18: 0.78 | G18: =INDEX($C18:$F18,1,$B$5) -> 1 | I18: Speed of the ramp toward peak occupancy
A19: ARPOB Year 1 (gross tariff) | B19: Rs/bed-day | C19: 26500 | D19: 28500 | E19: 24000 | F19: 22500 | G19: =INDEX($C19:$F19,1,$B$5) -> 26500 | I19: Gross of payer discount; net = gross x realisation index
A20: ARPOB escalation p.a. | B20: % | C20: 0.075 | D20: 0.08 | E20: 0.055 | F20: 0.045 | G20: =INDEX($C20:$F20,1,$B$5) -> 0.075 | I20: ICRA guides 6-8% p.a. for the sector
A21: OPD footfall multiplier | B21: x | C21: 1 | D21: 1.12 | E21: 0.88 | F21: 0.8 | G21: =INDEX($C21:$F21,1,$B$5) -> 1
A22: Consumables % of revenue | B22: % | C22: 0.23 | D22: 0.218 | E22: 0.242 | F22: 0.25 | G22: =INDEX($C22:$F22,1,$B$5) -> 0.23 | I22: Drugs, implants, surgical disposables, lab reagents
A23: Salary escalation p.a. | B23: % | C23: 0.08 | D23: 0.075 | E23: 0.09 | F23: 0.1 | G23: =INDEX($C23:$F23,1,$B$5) -> 0.08
A24: Consultant payout % of IPD+OPD | B24: % | C24: 0.11 | D24: 0.105 | E24: 0.12 | F24: 0.125 | G24: =INDEX($C24:$F24,1,$B$5) -> 0.11 | I24: Fee-for-service visiting consultants only; full-time consultants sit in salaries
A25: Capex overrun | B25: % | C25: 0 | D25: -0.03 | E25: 0.06 | F25: 0.12 | G25: =INDEX($C25:$F25,1,$B$5) -> 0 | I25: Applied to everything except land
A26: Base interest rate | B26: % | C26: 0.1075 | D26: 0.1 | E26: 0.115 | F26: 0.125 | G26: =INDEX($C26:$F26,1,$B$5) -> 0.1075 | I26: Market range for hospital term loans is 9.5-12.5%
A27: Construction delay | B27: months | C27: 0 | D27: 0 | E27: 3 | F27: 6 | G27: =INDEX($C27:$F27,1,$B$5) -> 0 | I27: Extends IDC and defers first revenue
A28: Exit EV/EBITDA multiple | B28: x | C28: 13 | D28: 15 | E28: 11 | F28: 9 | G28: =INDEX($C28:$F28,1,$B$5) -> 13 | I28: Unlisted tier-2 asset; listed Indian hospitals trade far higher
A31: FUNDING STRUCTURE TABLE
A32: Parameter | B32: Unit | C32: Opt 1: 70:30 | D32: Opt 2: 65:35 | E32: Opt 3: 60:40 + PE | G32: ACTIVE
A33: Term debt as % of cost of project | B33: % | C33: 0.7 | D33: 0.65 | E33: 0.6 | G33: =INDEX($C33:$E33,1,$B$8) -> 0.7 | I33: Cost of project excludes the promoter support facility
A34: Promoter support facility (DSRA + deficit) | B34: Rs Lakh | C34: 1780 | D34: 1587 | E34: 1450 | G34: =INDEX($C34:$E34,1,$B$8) -> 1780 | I34: Solved so the minimum cash balance stays >= Rs 150 L in the base case
A35: Interest rate adjustment | B35: % | C35: 0 | D35: -0.0015 | E35: -0.0025 | G35: =INDEX($C35:$E35,1,$B$8) -> 0 | I35: Lower leverage earns finer pricing
A36: Effective interest rate applied in the model | G36: =$G$26+$G$35 -> 0.1075
A39: PAYER MIX TABLE
A40: Payer segment | B40: Blended | C40: Govt-heavy | D40: Cash-premium | E40: ACTIVE mix | F40: Realisation vs list | G40: Debtor days
A41: Cash / self-pay | B41: 0.4 | C41: 0.3 | D41: 0.6 | E41: =INDEX($B41:$D41,1,$B$11) -> 0.4 | F41: 1 | G41: 3
A42: Private insurance / TPA | B42: 0.35 | C42: 0.25 | D42: 0.35 | E42: =INDEX($B42:$D42,1,$B$11) -> 0.35 | F42: 0.94 | G42: 55
A43: Government schemes (PMJAY / CGHS / ESI) | B43: 0.25 | C43: 0.45 | D43: 0.05 | E43: =INDEX($B43:$D43,1,$B$11) -> 0.25 | F43: 0.72 | G43: 110
A44: Total | B44: =SUM(B41:B43) -> 1 | C44: =SUM(C41:C43) -> 1 | D44: =SUM(D41:D43) -> 1 | E44: =SUM(E41:E43) -> 1
A45: Integrity check — active mix must total 100% | E45: =IF(ABS($E$44-1)<0.0001,"OK","ERROR - mix does not sum to 100%") -> OK
A47: Weighted realisation index | E47: =SUMPRODUCT($E$41:$E$43,$F$41:$F$43) -> 0.909 | I47: Net ARPOB = gross ARPOB x this index
A48: Weighted debtor days | E48: =SUMPRODUCT($E$41:$E$43,$G$41:$G$43) -> 47.95 | I48: Drives receivables on the Working Capital sheet
A51: HOW THIS MODEL IS WIRED
A52: Control Panel -> Assumptions -> Revenue Build / Manpower / Operating Costs -> P&L
A53: Capex & Funding -> Depreciation (into P&L) and Debt Schedule (interest into P&L)
...

Sheet Assumptions
A1: ASSUMPTIONS
A2: All amounts in Rs Lakh unless the unit column says otherwise. Blue on yellow = input. Source notes in column E.
A4: 1. CAPACITY & PHYSICAL PARAMETERS
A5: Operational beds | B5: beds | C5: 100 | E5: Licensed and commissioned bed strength
A6: Built-up area | B6: sq ft | C6: 105000 | E6: 1,050 sq ft per bed — NABH-compliant planning norm
A7: Land area | B7: acres | C7: 2 | E7: Allows FSI headroom for a Phase-2 vertical expansion
A8: Number of operation theatres | B8: nos | C8: 4 | E8: 3 major + 1 minor/emergency
A9: Critical care beds (ICU/CCU/NICU/HDU) | B9: beds | C9: 33 | E9: 33% of total — appropriate for a tier-2 tertiary-lite facility
A10: Dialysis stations | B10: nos | C10: 10
A11: Construction period | B11: months | C11: 18 | E11: From financial closure to commercial operation date (COD)
A12: Construction delay (from scenario) | B12: months | C12: ='Control Panel'!$G$27 -> 0 | E12: Linked to the Control Panel
A13: Effective construction period | B13: months | C13: =C11+C12 -> 18
A15: 2. BED CONFIGURATION
A16: Bed category | B16: Beds | C16: % of total
A17: General ward (multi-bedded) | B17: 34 | C17: =IFERROR(B17/$B$25,0) -> 0.34
A18: Semi-private (twin sharing) | B18: 18 | C18: =IFERROR(B18/$B$25,0) -> 0.18
A19: Private / deluxe room | B19: 12 | C19: =IFERROR(B19/$B$25,0) -> 0.12
A20: ICU — medical & surgical | B20: 14 | C20: =IFERROR(B20/$B$25,0) -> 0.14
A21: CCU — coronary care | B21: 6 | C21: =IFERROR(B21/$B$25,0) -> 0.06
A22: NICU / PICU | B22: 8 | C22: =IFERROR(B22/$B$25,0) -> 0.08
A23: HDU / step-down | B23: 5 | C23: =IFERROR(B23/$B$25,0) -> 0.05
A24: Isolation / negative pressure | B24: 3 | C24: =IFERROR(B24/$B$25,0) -> 0.03
A25: Total beds | B25: =SUM(B17:B24) -> 100 | C25: =SUM(C17:C24) -> 1
A26: Integrity check — bed config must equal operational beds | B26: =IF(B25=C5,"OK","ERROR") -> OK
A28: 3. OCCUPANCY & CASE-MIX DRIVERS
A29: Peak (stabilised) occupancy | B29: % | C29: ='Control Panel'!$G$17 -> 0.72 | E29: ICRA FY2026: sector occupancy 62-64%; well-run tier-2 65-75%
A30: Occupancy ramp multiplier | B30: x | C30: ='Control Panel'!$G$18 -> 1 | E30: Scenario lever on the speed of the ramp
A31: ARPOB Year 1 — gross of payer discount | B31: Rs/bed-day | C31: ='Control Panel'!$G$19 -> 26500 | E31: Average revenue per occupied bed-day at list tariff
A32: ARPOB escalation p.a. | B32: % | C32: ='Control Panel'!$G$20 -> 0.075 | E32: ICRA guides 6-8% p.a.; driven by tariff revision plus case-mix enrichment
A33: Weighted realisation index (payer mix) | B33: index | C33: ='Control Panel'!$E$47 -> 0.909 | E33: Net ARPOB = gross ARPOB x this index
A34: Average length of stay (ALOS) | B34: days | C34: 3.9 | E34: Used to derive admissions from bed-days
A36: Occupancy ramp profile — % of peak occupancy achieved
A37: Ramp factor | B37: Unit | C37: Year 1 | D37: Year 2 | E37: Year 3 | F37: Year 4 | G37: Year 5 | H37: Year 6 | I37: Year 7 | J37: Year 8 | K37: Year 9 | L37: Year 10
A38: Financial year | C38: FY2029 | D38: FY2030 | E38: FY2031 | F38: FY2032 | G38: FY2033 | H38: FY2034 | I38: FY2035 | J38: FY2036 | K38: FY2037 | L38: FY2038
A39: % of peak occupancy achieved | B39: % | C39: 0.38 | D39: 0.6 | E39: 0.78 | F39: 0.89 | G39: 0.97 | H39: 1 | I39: 1 | J39: 1 | K39: 1 | L39: 1 | N39: Blue inputs — the shape of the ramp is a management judgement
A40: Occupancy achieved | B40: % | C40: =MIN($C$29*C39*$C$30,0.92) -> 0.2736 | D40: =MIN($C$29*D39*$C$30,0.92) -> 0.432 | E40: =MIN($C$29*E39*$C$30,0.92) -> 0.5616 | F40: =MIN($C$29*F39*$C$30,0.92) -> 0.6408 | G40: =MIN($C$29*G39*$C$30,0.92) -> 0.6984 | H40: =MIN($C$29*H39*$C$30,0.92) -> 0.72 | I40: =MIN($C$29*I39*$C$30,0.92) -> 0.72 | J40: =MIN($C$29*J39*$C$30,0.92) -> 0.72 | ... L40: =MIN($C$29*L39*$C$30,0.92) -> 0.72 | N40: Capped at 92% — physical maximum with turnaround time
A42: 4. OUTPATIENT, DIAGNOSTICS, PHARMACY & DIALYSIS DRIVERS
A43: OPD footfall multiplier | B43: x | C43: ='Control Panel'!$G$21 -> 1
A44: OPD footfall Year 1 | B44: patients/day | C44: 100 | E44: Ramps per the profile below
A45: Net revenue per OPD visit — Year 1 | B45: Rs | C45: 700 | E45: Consultation + procedure charges retained
...

Sheet Capex & Funding
A1: COST OF PROJECT & MEANS OF FINANCE
A2: All amounts in Rs Lakh. IDC is solved in closed form to avoid the classic circular reference.
A4: A. COST OF PROJECT
A5: Cost head | B5: Basis | C5: Amount | D5: % of total
A6: Land — 2.0 acres freehold | B6: 2.0 ac @ Rs 550 L/acre | C6: =2*550 -> 1100 | D6: =IFERROR(C6/$C$25,0) -> 0.09930031
A7: Site development, boundary wall & approach | B7: Lump sum | C7: =150*(1+'Control Panel'!$G$25) -> 150 | D7: =IFERROR(C7/$C$25,0) -> 0.013540951
A8: Civil construction | B8: 1,05,000 sq ft @ Rs 2,700/sq ft | C8: =Assumptions!$C$6*2700/100000*(1+'Control Panel'!$G$25) -> 2835 | D8: =IFERROR(C8/$C$25,0) -> 0.25592398
A9: MEP & building services | B9: @ Rs 950/sq ft — HVAC, electrical, plumbing, medical gas, fire | C9: =Assumptions!$C$6*950/100000*(1+'Control Panel'!$G$25) -> 997.5 | D9: =IFERROR(C9/$C$25,0) -> 0.090047327
A10: Interiors & finishes | B10: @ Rs 520/sq ft | C10: =Assumptions!$C$6*520/100000*(1+'Control Panel'!$G$25) -> 546 | D10: =IFERROR(C10/$C$25,0) -> 0.049289063
A11: Medical equipment | B11: See equipment schedule below | C11: =2650*(1+'Control Panel'!$G$25) -> 2650 | D11: =IFERROR(C11/$C$25,0) -> 0.23922347
A12: Non-medical equipment & utilities | B12: DG sets, lifts, CSSD, laundry, kitchen, STP | C12: =620*(1+'Control Panel'!$G$25) -> 620 | D12: =IFERROR(C12/$C$25,0) -> 0.055969266
A13: Furniture & fixtures | B13: Beds, cots, cabinets, workstations | C13: =300*(1+'Control Panel'!$G$25) -> 300 | D13: =IFERROR(C13/$C$25,0) -> 0.027081903
A14: IT, HIS & PACS | B14: HIS/HMIS licence, servers, network, PACS, CCTV | C14: =185*(1+'Control Panel'!$G$25) -> 185 | D14: =IFERROR(C14/$C$25,0) -> 0.016700507
A15: Pre-operative expenses | B15: Licences, consultancy, recruitment, pre-launch marketing, trial run | C15: =450*(1+'Control Panel'!$G$25) -> 450 | D15: =IFERROR(C15/$C$25,0) -> 0.040622854
A16: Contingency @ 4% | B16: On hard cost excl. land and pre-operative | C16: =0.04*(SUM(C7:C14)) -> 331.34 | D16: =IFERROR(C16/$C$25,0) -> 0.029911059
A17: Margin money for working capital | B17: Promoter's contribution to working capital | C17: 350 | D17: =IFERROR(C17/$C$25,0) -> 0.031595553
A18: Hard cost (before IDC) | C18: =SUM(C6:C17) -> 10514.84 | D18: =IFERROR(C18/$C$25,0) -> 0.94920625
D19: =IFERROR(C19/$C$25,0) -> 0
A20: Interest during construction (IDC) — closed-form solution | D20: =IFERROR(C20/$C$25,0) -> 0
A21: IDC depends on the debt, the debt depends on the project cost, and the project cost includes IDC. | D21: =IFERROR(C21/$C$25,0) -> 0
A22: Rather than iterate, solve algebraically: IDC = k x HardCost / (1 - k), where k = d x r x (m/12) x f | D22: =IFERROR(C22/$C$25,0) -> 0
A23: k = debt% x rate x (months/12) x drawdown factor | C23: =Assumptions!$C$105*Assumptions!$C$106*(Assumptions!$C$13/12)*Assumptions!$C$111 -> 0.05079375 | D23: =IFERROR(C23/$C$25,0) -> 4.5853047e-06
A24: Interest during construction (IDC) | B24: Capitalised into the asset blocks | C24: =C23*C18/(1-C23) -> 562.66818 | D24: =IFERROR(C24/$C$25,0) -> 0.05079375
A25: TOTAL COST OF PROJECT | C25: =C18+C24 -> 11077.508 | D25: =C25/$C$25 -> 1 | F25: This is the figure the lender appraises and lends against.
A27: Cost per operational bed | C27: =C25/Assumptions!$C$5 -> 110.77508 | F27: Benchmark: Rs 70-100 L/bed ex-land for a metro build; this project carries a cath lab, CT, 4 OTs and 33 critical-care beds.
A28: Cost per bed excluding land | C28: =(C25-C6)/Assumptions!$C$5 -> 99.775082
A30: B. MEANS OF FINANCE
A31: Source | B31: Basis | C31: Amount | D31: % of cost of project
A32: Term loan from bank / FI | B32: Per the active funding structure | C32: =C25*Assumptions!$C$105 -> 7754.2557 | D32: =C32/$C$25 -> 0.7
A33: Promoter equity (incl. land contributed in kind) | C33: =C25-C32 -> 3323.2525 | D33: =C33/$C$25 -> 0.3
A34: Total means of finance — cost of project | C34: =C32+C33 -> 11077.508 | D34: =C34/$C$25 -> 1
A35: Integrity check — means of finance must equal cost of project | C35: =IF(ABS(C34-C25)<0.01,"OK","ERROR") -> OK
A37: Additional promoter commitment — outside the cost of project
A38: Promoter support facility (DSRA + start-up operating deficit) | B38: Unsecured subordinated promoter loan / equity | C38: =Assumptions!$C$112 -> 1780 | F38: A greenfield hospital loses money for roughly two years. Banks do not lend against operating losses, so the promoter must commit this separately. Sized so the minimum cash balance stays positive.
A39: TOTAL FUNDING REQUIREMENT | C39: =C34+C38 -> 12857.508
A40: Term debt as % of TOTAL funding requirement | C40: =C32/C39 -> 0.60309164 | F40: Headline gearing is 70:30 on the cost of project, but only ~60:40 once the promoter's cash-flow support is counted. Both views matter — quote the first to a lender, the second to yourself.
A41: Total promoter contribution | C41: =C33+C38 -> 5103.2525 | D41: =C41/C39 -> 0.39690836
A42: Upfront processing fee on term loan | C42: =C32*Assumptions!$C$107 -> 77.542557
A44: C. MEDICAL EQUIPMENT SCHEDULE
A45: Equipment | B45: Qty | C45: Rs Lakh | D45: Note
...

Sheet Depreciation
A1: DEPRECIATION & AMORTISATION SCHEDULE
A2: Book depreciation on the straight-line method (Companies Act 2013, Schedule II). Rs Lakh.
A4: Particulars | B4: Basis | C4: Year 1 | D4: Year 2 | E4: Year 3 | F4: Year 4 | G4: Year 5 | H4: Year 6 | I4: Year 7 | J4: Year 8 | K4: Year 9 | L4: Year 10
A5: Financial year | C5: FY2029 | D5: FY2030 | E5: FY2031 | F5: FY2032 | G5: FY2033 | H5: FY2034 | I5: FY2035 | J5: FY2036 | K5: FY2037 | L5: FY2038
A6: Maintenance capex incurred in the year | B6: Rs Lakh | C6: =IF(1>=3,Assumptions!$C$94*'Revenue Build'!C$43,0) -> 0 | D6: =IF(2>=3,Assumptions!$C$94*'Revenue Build'!D$43,0) -> 0 | E6: =IF(3>=3,Assumptions!$C$94*'Revenue Build'!E$43,0) -> 144.09758 | F6: =IF(4>=3,Assumptions!$C$94*'Revenue Build'!F$43,0) -> 177.60471 | G6: =IF(5>=3,Assumptions!$C$94*'Revenue Build'!G$43,0) -> 208.78917 | H6: =IF(6>=3,Assumptions!$C$94*'Revenue Build'!H$43,0) -> 232.44099 | I6: =IF(7>=3,Assumptions!$C$94*'Revenue Build'!I$43,0) -> 252.05481 | J6: =IF(8>=3,Assumptions!$C$94*'Revenue Build'!J$43,0) -> 271.83259 | K6: =IF(9>=3,Assumptions!$C$94*'Revenue Build'!K$43,0) -> 293.68097 | L6: =IF(10>=3,Assumptions!$C$94*'Revenue Build'!L$43,0) -> 316.61633
A7: Expansion capex — MRI (Year 3) | B7: Rs Lakh | C7: =0 -> 0 | D7: =0 -> 0 | E7: =Assumptions!$C$95 -> 550 | F7: =0 -> 0 | G7: =0 -> 0 | H7: =0 -> 0 | I7: =0 -> 0 | J7: =0 -> 0 | K7: =0 -> 0 | L7: =0 -> 0
A8: Total capex in the year | B8: Rs Lakh | C8: =C6+C7 -> 0 | D8: =D6+D7 -> 0 | E8: =E6+E7 -> 694.09758 | F8: =F6+F7 -> 177.60471 | G8: =G6+G7 -> 208.78917 | H8: =H6+H7 -> 232.44099 | I8: =I6+I7 -> 252.05481 | J8: =J6+J7 -> 271.83259 | ... L8: =L6+L7 -> 316.61633
A10: Depreciation by block
A11: Building, civil, MEP & interiors | B11: Rs Lakh | C11: ='Capex & Funding'!$C$65*'Capex & Funding'!$D$65 -> 167.57597 | D11: ='Capex & Funding'!$C$65*'Capex & Funding'!$D$65 -> 167.57597 | E11: ='Capex & Funding'!$C$65*'Capex & Funding'!$D$65 -> 167.57597 | F11: ='Capex & Funding'!$C$65*'Capex & Funding'!$D$65 -> 167.57597 | G11: ='Capex & Funding'!$C$65*'Capex & Funding'!$D$65 -> 167.57597 | H11: ='Capex & Funding'!$C$65*'Capex & Funding'!$D$65 -> 167.57597 | I11: ='Capex & Funding'!$C$65*'Capex & Funding'!$D$65 -> 167.57597 | J11: ='Capex & Funding'!$C$65*'Capex & Funding'!$D$65 -> 167.57597 | ... L11: ='Capex & Funding'!$C$65*'Capex & Funding'!$D$65 -> 167.57597
A12: Medical equipment (incl. MRI from Year 3) | B12: Rs Lakh | C12: =('Capex & Funding'!$C$66)*'Capex & Funding'!$D$66 -> 220.20037 | D12: =('Capex & Funding'!$C$66)*'Capex & Funding'!$D$66 -> 220.20037 | E12: =('Capex & Funding'!$C$66+Assumptions!$C$95)*'Capex & Funding'!$D$66 -> 261.45037 | F12: =('Capex & Funding'!$C$66+Assumptions!$C$95)*'Capex & Funding'!$D$66 -> 261.45037 | G12: =('Capex & Funding'!$C$66+Assumptions!$C$95)*'Capex & Funding'!$D$66 -> 261.45037 | H12: =('Capex & Funding'!$C$66+Assumptions!$C$95)*'Capex & Funding'!$D$66 -> 261.45037 | I12: =('Capex & Funding'!$C$66+Assumptions!$C$95)*'Capex & Funding'!$D$66 -> 261.45037 | J12: =('Capex & Funding'!$C$66+Assumptions!$C$95)*'Capex & Funding'!$D$66 -> 261.45037 | K12: =('Capex & Funding'!$C$66+Assumptions!$C$95)*'Capex & Funding'!$D$66 -> 261.45037 | L12: =('Capex & Funding'!$C$66+Assumptions!$C$95)*'Capex & Funding'!$D$66 -> 261.45037
A13: Non-medical equipment & utilities | B13: Rs Lakh | C13: ='Capex & Funding'!$C$67*'Capex & Funding'!$D$67 -> 68.691436 | D13: ='Capex & Funding'!$C$67*'Capex & Funding'!$D$67 -> 68.691436 | E13: ='Capex & Funding'!$C$67*'Capex & Funding'!$D$67 -> 68.691436 | F13: ='Capex & Funding'!$C$67*'Capex & Funding'!$D$67 -> 68.691436 | G13: ='Capex & Funding'!$C$67*'Capex & Funding'!$D$67 -> 68.691436 | H13: ='Capex & Funding'!$C$67*'Capex & Funding'!$D$67 -> 68.691436 | I13: ='Capex & Funding'!$C$67*'Capex & Funding'!$D$67 -> 68.691436 | J13: ='Capex & Funding'!$C$67*'Capex & Funding'!$D$67 -> 68.691436 | ... L13: ='Capex & Funding'!$C$67*'Capex & Funding'!$D$67 -> 68.691436
A14: Furniture & fixtures | B14: Rs Lakh | C14: ='Capex & Funding'!$C$68*'Capex & Funding'!$D$68 -> 33.237791 | D14: ='Capex & Funding'!$C$68*'Capex & Funding'!$D$68 -> 33.237791 | E14: ='Capex & Funding'!$C$68*'Capex & Funding'!$D$68 -> 33.237791 | F14: ='Capex & Funding'!$C$68*'Capex & Funding'!$D$68 -> 33.237791 | G14: ='Capex & Funding'!$C$68*'Capex & Funding'!$D$68 -> 33.237791 | H14: ='Capex & Funding'!$C$68*'Capex & Funding'!$D$68 -> 33.237791 | I14: ='Capex & Funding'!$C$68*'Capex & Funding'!$D$68 -> 33.237791 | J14: ='Capex & Funding'!$C$68*'Capex & Funding'!$D$68 -> 33.237791 | ... L14: ='Capex & Funding'!$C$68*'Capex & Funding'!$D$68 -> 33.237791
A15: IT, HIS & PACS (6-year life — fully written off after Year 6) | B15: Rs Lakh | C15: ='Capex & Funding'!$C$69*'Capex & Funding'!$D$69 -> 34.167896 | D15: ='Capex & Funding'!$C$69*'Capex & Funding'!$D$69 -> 34.167896 | E15: ='Capex & Funding'!$C$69*'Capex & Funding'!$D$69 -> 34.167896 | F15: ='Capex & Funding'!$C$69*'Capex & Funding'!$D$69 -> 34.167896 | G15: ='Capex & Funding'!$C$69*'Capex & Funding'!$D$69 -> 34.167896 | H15: ='Capex & Funding'!$C$69*'Capex & Funding'!$D$69 -> 34.167896 | I15: =0 -> 0 | J15: =0 -> 0 | K15: =0 -> 0 | L15: =0 -> 0
A16: Pre-operative expenses — amortisation | B16: Rs Lakh | C16: ='Capex & Funding'!$C$70/Assumptions!$C$93 -> 90 | D16: ='Capex & Funding'!$C$70/Assumptions!$C$93 -> 90 | E16: ='Capex & Funding'!$C$70/Assumptions!$C$93 -> 90 | F16: ='Capex & Funding'!$C$70/Assumptions!$C$93 -> 90 | G16: ='Capex & Funding'!$C$70/Assumptions!$C$93 -> 90 | H16: =0 -> 0 | I16: =0 -> 0 | J16: =0 -> 0 | K16: =0 -> 0 | L16: =0 -> 0
A17: Depreciation on maintenance capex @ 10% | B17: Rs Lakh | C17: =0 -> 0 | D17: =SUM($C$6:C6)*0.1 -> 0 | E17: =SUM($C$6:D6)*0.1 -> 0 | F17: =SUM($C$6:E6)*0.1 -> 14.409758 | G17: =SUM($C$6:F6)*0.1 -> 32.170229 | H17: =SUM($C$6:G6)*0.1 -> 53.049146 | I17: =SUM($C$6:H6)*0.1 -> 76.293246 | J17: =SUM($C$6:I6)*0.1 -> 101.49873 | K17: =SUM($C$6:J6)*0.1 -> 128.68199 | L17: =SUM($C$6:K6)*0.1 -> 158.05008
A18: TOTAL DEPRECIATION & AMORTISATION | B18: Rs Lakh | C18: =SUM(C11:C17) -> 613.87346 | D18: =SUM(D11:D17) -> 613.87346 | E18: =SUM(E11:E17) -> 655.12346 | F18: =SUM(F11:F17) -> 669.53322 | G18: =SUM(G11:G17) -> 687.29369 | H18: =SUM(H11:H17) -> 618.17261 | I18: =SUM(I11:I17) -> 607.24881 | J18: =SUM(J11:J17) -> 632.45429 | ... L18: =SUM(L11:L17) -> 689.00565
A20: Net block roll-forward
A21: Opening net block | B21: Rs Lakh | C21: ='Capex & Funding'!$C$72 -> 10727.508 | D21: =C22 -> 10113.635 | E21: =D22 -> 9499.7613 | F21: =E22 -> 9538.7354 | G21: =F22 -> 9046.8069 | H21: =G22 -> 8568.3024 | I21: =H22 -> 8182.5707 | J21: =I22 -> 7827.3767 | K21: =J22 -> 7466.755 | L21: =K22 -> 7100.7985
A22: Closing net block | B22: Rs Lakh | C22: =C21+C8-C18 -> 10113.635 | D22: =D21+D8-D18 -> 9499.7613 | E22: =E21+E8-E18 -> 9538.7354 | F22: =F21+F8-F18 -> 9046.8069 | G22: =G21+G8-G18 -> 8568.3024 | H22: =H21+H8-H18 -> 8182.5707 | I22: =I21+I8-I18 -> 7827.3767 | J22: =J21+J8-J18 -> 7466.755 | ... L22: =L21+L8-L18 -> 6728.4091
A24: Income-tax depreciation is computed on the written-down-value method at different rates (building 10%, plant &
A25: machinery 15%, computers 40%), which produces a timing difference and therefore a deferred tax liability. This model
A26: computes tax on book profit for simplicity and flags the difference below rather than maintaining a full DTA/DTL schedule.
A28: Income-tax depreciation (WDV) — for deferred-tax context only
A29: Opening WDV — plant & machinery block | B29: Rs Lakh | C29: ='Capex & Funding'!$C$66+'Capex & Funding'!$C$67+'Capex & Funding'!$C$68 -> 3955.2972 | D29: =C31 -> 3362.0026 | E29: =D31 -> 2857.7022 | F29: =E31 -> 2429.0469 | G29: =F31 -> 2064.6898 | H29: =G31 -> 1754.9864 | I29: =H31 -> 1491.7384 | J29: =I31 -> 1267.9777 | K29: =J31 -> 1077.781 | L29: =K31 -> 916.11385
A30: Income-tax depreciation @ 15% WDV | B30: Rs Lakh | C30: =C29*Assumptions!$C$101 -> 593.29458 | D30: =D29*Assumptions!$C$101 -> 504.30039 | E30: =E29*Assumptions!$C$101 -> 428.65533 | F30: =F29*Assumptions!$C$101 -> 364.35703 | G30: =G29*Assumptions!$C$101 -> 309.70348 | H30: =H29*Assumptions!$C$101 -> 263.24796 | I30: =I29*Assumptions!$C$101 -> 223.76076 | J30: =J29*Assumptions!$C$101 -> 190.19665 | ... L30: =L29*Assumptions!$C$101 -> 137.41708
A31: Closing WDV | B31: Rs Lakh | C31: =C29-C30 -> 3362.0026 | D31: =D29-D30 -> 2857.7022 | E31: =E29-E30 -> 2429.0469 | F31: =F29-F30 -> 2064.6898 | G31: =G29-G30 -> 1754.9864 | H31: =H29-H30 -> 1491.7384 | I31: =I29-I30 -> 1267.9777 | J31: =J29-J30 -> 1077.781 | ... L31: =L29-L30 -> 778.69678
A32: Timing difference vs book depreciation on the same blocks | B32: Rs Lakh | C32: =C30-(C12+C13+C14) -> 271.16498 | D32: =D30-(D12+D13+D14) -> 182.1708 | E32: =E30-(E12+E13+E14) -> 65.275737 | F32: =F30-(F12+F13+F14) -> 0.97743686 | G32: =G30-(G12+G13+G14) -> -53.676118 | H32: =H30-(H12+H13+H14) -> -100.13164 | I32: =I30-(I12+I13+I14) -> -139.61883 | J32: =J30-(J12+J13+J14) -> -173.18295 | ... L32: =L30-(L12+L13+L14) -> -225.96252 | N32: Positive = tax depreciation exceeds book, creating a DTL

Sheet Revenue Build
A1: REVENUE BUILD-UP
A2: Bottom-up: bed-days x ARPOB for inpatient, footfall x ticket for outpatient. Rs Lakh unless stated.
A4: Particulars | B4: Unit | C4: Year 1 | D4: Year 2 | E4: Year 3 | F4: Year 4 | G4: Year 5 | H4: Year 6 | I4: Year 7 | J4: Year 8 | K4: Year 9 | L4: Year 10
A5: Financial year | C5: FY2029 | D5: FY2030 | E5: FY2031 | F5: FY2032 | G5: FY2033 | H5: FY2034 | I5: FY2035 | J5: FY2036 | K5: FY2037 | L5: FY2038
A6: A. Inpatient department (IPD)
A7: Operational beds | B7: beds | C7: =Assumptions!$C$5 -> 100 | D7: =Assumptions!$C$5 -> 100 | E7: =Assumptions!$C$5 -> 100 | F7: =Assumptions!$C$5 -> 100 | G7: =Assumptions!$C$5 -> 100 | H7: =Assumptions!$C$5 -> 100 | I7: =Assumptions!$C$5 -> 100 | J7: =Assumptions!$C$5 -> 100 | ... L7: =Assumptions!$C$5 -> 100
A8: Occupancy | B8: % | C8: =Assumptions!C$40 -> 0.2736 | D8: =Assumptions!D$40 -> 0.432 | E8: =Assumptions!E$40 -> 0.5616 | F8: =Assumptions!F$40 -> 0.6408 | G8: =Assumptions!G$40 -> 0.6984 | H8: =Assumptions!H$40 -> 0.72 | I8: =Assumptions!I$40 -> 0.72 | J8: =Assumptions!J$40 -> 0.72 | ... L8: =Assumptions!L$40 -> 0.72
A9: Occupied bed-days | B9: bed-days | C9: =C7*365*C8 -> 9986.4 | D9: =D7*365*D8 -> 15768 | E9: =E7*365*E8 -> 20498.4 | F9: =F7*365*F8 -> 23389.2 | G9: =G7*365*G8 -> 25491.6 | H9: =H7*365*H8 -> 26280 | I9: =I7*365*I8 -> 26280 | J9: =J7*365*J8 -> 26280 | ... L9: =L7*365*L8 -> 26280
A10: Average length of stay | B10: days | C10: =Assumptions!$C$34 -> 3.9 | D10: =Assumptions!$C$34 -> 3.9 | E10: =Assumptions!$C$34 -> 3.9 | F10: =Assumptions!$C$34 -> 3.9 | G10: =Assumptions!$C$34 -> 3.9 | H10: =Assumptions!$C$34 -> 3.9 | I10: =Assumptions!$C$34 -> 3.9 | J10: =Assumptions!$C$34 -> 3.9 | ... L10: =Assumptions!$C$34 -> 3.9
A11: Admissions (discharges) | B11: patients | C11: =C9/C10 -> 2560.6154 | D11: =D9/D10 -> 4043.0769 | E11: =E9/E10 -> 5256 | F11: =F9/F10 -> 5997.2308 | G11: =G9/G10 -> 6536.3077 | H11: =H9/H10 -> 6738.4615 | I11: =I9/I10 -> 6738.4615 | J11: =J9/J10 -> 6738.4615 | ... L11: =L9/L10 -> 6738.4615
A12: ARPOB — gross of payer discount | B12: Rs/bed-day | C12: =Assumptions!$C$31*(1+Assumptions!$C$32)^0 -> 26500 | D12: =Assumptions!$C$31*(1+Assumptions!$C$32)^1 -> 28487.5 | E12: =Assumptions!$C$31*(1+Assumptions!$C$32)^2 -> 30624.062 | F12: =Assumptions!$C$31*(1+Assumptions!$C$32)^3 -> 32920.867 | G12: =Assumptions!$C$31*(1+Assumptions!$C$32)^4 -> 35389.932 | H12: =Assumptions!$C$31*(1+Assumptions!$C$32)^5 -> 38044.177 | I12: =Assumptions!$C$31*(1+Assumptions!$C$32)^6 -> 40897.49 | J12: =Assumptions!$C$31*(1+Assumptions!$C$32)^7 -> 43964.802 | K12: =Assumptions!$C$31*(1+Assumptions!$C$32)^8 -> 47262.162 | L12: =Assumptions!$C$31*(1+Assumptions!$C$32)^9 -> 50806.825
A13: Weighted realisation index (payer mix) | B13: index | C13: =Assumptions!$C$33 -> 0.909 | D13: =Assumptions!$C$33 -> 0.909 | E13: =Assumptions!$C$33 -> 0.909 | F13: =Assumptions!$C$33 -> 0.909 | G13: =Assumptions!$C$33 -> 0.909 | H13: =Assumptions!$C$33 -> 0.909 | I13: =Assumptions!$C$33 -> 0.909 | J13: =Assumptions!$C$33 -> 0.909 | ... L13: =Assumptions!$C$33 -> 0.909
A14: ARPOB — net realised | B14: Rs/bed-day | C14: =C12*C13 -> 24088.5 | D14: =D12*D13 -> 25895.138 | E14: =E12*E13 -> 27837.273 | F14: =F12*F13 -> 29925.068 | G14: =G12*G13 -> 32169.448 | H14: =H12*H13 -> 34582.157 | I14: =I12*I13 -> 37175.819 | J14: =J12*J13 -> 39964.005 | ... L14: =L12*L13 -> 46183.404
A15: IPD revenue | B15: Rs Lakh | C15: =C9*C14/100000 -> 2405.574 | D15: =D9*D14/100000 -> 4083.1453 | E15: =E9*E14/100000 -> 5706.1955 | F15: =F9*F14/100000 -> 6999.2341 | G15: =G9*G14/100000 -> 8200.5071 | H15: =H9*H14/100000 -> 9088.1909 | I15: =I9*I14/100000 -> 9769.8052 | J15: =J9*J14/100000 -> 10502.541 | ... L15: =L9*L14/100000 -> 12136.998 | N15: ARPOB by convention includes drugs and diagnostics consumed by inpatients
A17: B. Outpatient department (OPD)
A18: OPD footfall per day | B18: patients/day | C18: =Assumptions!$C$44*Assumptions!C$58*Assumptions!$C$43 -> 100 | D18: =Assumptions!$C$44*Assumptions!D$58*Assumptions!$C$43 -> 160 | E18: =Assumptions!$C$44*Assumptions!E$58*Assumptions!$C$43 -> 220 | F18: =Assumptions!$C$44*Assumptions!F$58*Assumptions!$C$43 -> 260 | G18: =Assumptions!$C$44*Assumptions!G$58*Assumptions!$C$43 -> 290 | H18: =Assumptions!$C$44*Assumptions!H$58*Assumptions!$C$43 -> 310 | I18: =Assumptions!$C$44*Assumptions!I$58*Assumptions!$C$43 -> 325 | J18: =Assumptions!$C$44*Assumptions!J$58*Assumptions!$C$43 -> 335 | ... L18: =Assumptions!$C$44*Assumptions!L$58*Assumptions!$C$43 -> 355
A19: Annual OPD visits | B19: visits | C19: =C18*365 -> 36500 | D19: =D18*365 -> 58400 | E19: =E18*365 -> 80300 | F19: =F18*365 -> 94900 | G19: =G18*365 -> 105850 | H19: =H18*365 -> 113150 | I19: =I18*365 -> 118625 | J19: =J18*365 -> 122275 | ... L19: =L18*365 -> 129575
A20: Net revenue per visit | B20: Rs | C20: =Assumptions!$C$45*(1+Assumptions!$C$46)^0 -> 700 | D20: =Assumptions!$C$45*(1+Assumptions!$C$46)^1 -> 742 | E20: =Assumptions!$C$45*(1+Assumptions!$C$46)^2 -> 786.52 | F20: =Assumptions!$C$45*(1+Assumptions!$C$46)^3 -> 833.7112 | G20: =Assumptions!$C$45*(1+Assumptions!$C$46)^4 -> 883.73387 | H20: =Assumptions!$C$45*(1+Assumptions!$C$46)^5 -> 936.7579 | I20: =Assumptions!$C$45*(1+Assumptions!$C$46)^6 -> 992.96338 | J20: =Assumptions!$C$45*(1+Assumptions!$C$46)^7 -> 1052.5412 | K20: =Assumptions!$C$45*(1+Assumptions!$C$46)^8 -> 1115.6937 | L20: =Assumptions!$C$45*(1+Assumptions!$C$46)^9 -> 1182.6353
A21: OPD revenue | B21: Rs Lakh | C21: =C19*C20/100000 -> 255.5 | D21: =D19*D20/100000 -> 433.328 | E21: =E19*E20/100000 -> 631.57556 | F21: =F19*F20/100000 -> 791.19193 | G21: =G19*G20/100000 -> 935.4323 | H21: =H19*H20/100000 -> 1059.9416 | I21: =I19*I20/100000 -> 1177.9028 | J21: =J19*J20/100000 -> 1286.9947 | ... L21: =L19*L20/100000 -> 1532.3997
A23: C. Outpatient diagnostics (radiology & laboratory)
A24: Conversion — share of OPD footfall | B24: % | C24: =Assumptions!C$59 -> 0.45 | D24: =Assumptions!D$59 -> 0.47 | E24: =Assumptions!E$59 -> 0.48 | F24: =Assumptions!F$59 -> 0.49 | G24: =Assumptions!G$59 -> 0.5 | H24: =Assumptions!H$59 -> 0.5 | I24: =Assumptions!I$59 -> 0.51 | J24: =Assumptions!J$59 -> 0.51 | ... L24: =Assumptions!L$59 -> 0.52
A25: Average ticket size | B25: Rs | C25: =Assumptions!$C$48*(1+Assumptions!$C$46)^0 -> 950 | D25: =Assumptions!$C$48*(1+Assumptions!$C$46)^1 -> 1007 | E25: =Assumptions!$C$48*(1+Assumptions!$C$46)^2 -> 1067.42 | F25: =Assumptions!$C$48*(1+Assumptions!$C$46)^3 -> 1131.4652 | G25: =Assumptions!$C$48*(1+Assumptions!$C$46)^4 -> 1199.3531 | H25: =Assumptions!$C$48*(1+Assumptions!$C$46)^5 -> 1271.3143 | I25: =Assumptions!$C$48*(1+Assumptions!$C$46)^6 -> 1347.5932 | J25: =Assumptions!$C$48*(1+Assumptions!$C$46)^7 -> 1428.4487 | K25: =Assumptions!$C$48*(1+Assumptions!$C$46)^8 -> 1514.1557 | L25: =Assumptions!$C$48*(1+Assumptions!$C$46)^9 -> 1605.005
A26: Diagnostics revenue | B26: Rs Lakh | C26: =C19*C24*C25/100000 -> 156.0375 | D26: =D19*D24*D25/100000 -> 276.40136 | E26: =E19*E24*E25/100000 -> 411.42636 | F26: =F19*F24*F25/100000 -> 526.14263 | G26: =G19*G24*G25/100000 -> 634.75763 | H26: =H19*H24*H25/100000 -> 719.24606 | I26: =I19*I24*I25/100000 -> 815.27701 | J26: =J19*J24*J25/100000 -> 890.78421 | ... L26: =L19*L24*L25/100000 -> 1081.4363
A28: D. Outpatient pharmacy
A29: Conversion — share of OPD footfall | B29: % | C29: =Assumptions!C$60 -> 0.55 | D29: =Assumptions!D$60 -> 0.57 | E29: =Assumptions!E$60 -> 0.58 | F29: =Assumptions!F$60 -> 0.59 | G29: =Assumptions!G$60 -> 0.6 | H29: =Assumptions!H$60 -> 0.6 | I29: =Assumptions!I$60 -> 0.61 | J29: =Assumptions!J$60 -> 0.61 | ... L29: =Assumptions!L$60 -> 0.62
A30: Average ticket size | B30: Rs | C30: =Assumptions!$C$50*(1+Assumptions!$C$46)^0 -> 480 | D30: =Assumptions!$C$50*(1+Assumptions!$C$46)^1 -> 508.8 | E30: =Assumptions!$C$50*(1+Assumptions!$C$46)^2 -> 539.328 | F30: =Assumptions!$C$50*(1+Assumptions!$C$46)^3 -> 571.68768 | G30: =Assumptions!$C$50*(1+Assumptions!$C$46)^4 -> 605.98894 | H30: =Assumptions!$C$50*(1+Assumptions!$C$46)^5 -> 642.34828 | I30: =Assumptions!$C$50*(1+Assumptions!$C$46)^6 -> 680.88917 | J30: =Assumptions!$C$50*(1+Assumptions!$C$46)^7 -> 721.74252 | K30: =Assumptions!$C$50*(1+Assumptions!$C$46)^8 -> 765.04708 | L30: =Assumptions!$C$50*(1+Assumptions!$C$46)^9 -> 810.9499
A31: Pharmacy revenue | B31: Rs Lakh | C31: =C19*C29*C30/100000 -> 96.36 | D31: =D19*D29*D30/100000 -> 169.36934 | E31: =E19*E29*E30/100000 -> 251.18662 | F31: =F19*F29*F30/100000 -> 320.09365 | G31: =G19*G29*G30/100000 -> 384.86358 | H31: =H19*H29*H30/100000 -> 436.09025 | I31: =I19*I29*I30/100000 -> 492.69992 | J31: =J19*J29*J30/100000 -> 538.33151 | ... L31: =L19*L29*L30/100000 -> 651.48877
A33: E. Dialysis unit
A34: Session capacity | B34: sessions | C34: =Assumptions!$C$51*Assumptions!$C$52*Assumptions!$C$53 -> 10500 | D34: =Assumptions!$C$51*Assumptions!$C$52*Assumptions!$C$53 -> 10500 | E34: =Assumptions!$C$51*Assumptions!$C$52*Assumptions!$C$53 -> 10500 | F34: =Assumptions!$C$51*Assumptions!$C$52*Assumptions!$C$53 -> 10500 | G34: =Assumptions!$C$51*Assumptions!$C$52*Assumptions!$C$53 -> 10500 | H34: =Assumptions!$C$51*Assumptions!$C$52*Assumptions!$C$53 -> 10500 | I34: =Assumptions!$C$51*Assumptions!$C$52*Assumptions!$C$53 -> 10500 | J34: =Assumptions!$C$51*Assumptions!$C$52*Assumptions!$C$53 -> 10500 | ... L34: =Assumptions!$C$51*Assumptions!$C$52*Assumptions!$C$53 -> 10500
A35: Utilisation | B35: % | C35: =Assumptions!C$61 -> 0.3 | D35: =Assumptions!D$61 -> 0.45 | E35: =Assumptions!E$61 -> 0.6 | F35: =Assumptions!F$61 -> 0.68 | G35: =Assumptions!G$61 -> 0.75 | H35: =Assumptions!H$61 -> 0.8 | I35: =Assumptions!I$61 -> 0.82 | J35: =Assumptions!J$61 -> 0.83 | ... L35: =Assumptions!L$61 -> 0.85
A36: Revenue per session | B36: Rs | C36: =Assumptions!$C$54*(1+Assumptions!$C$46)^0 -> 1900 | D36: =Assumptions!$C$54*(1+Assumptions!$C$46)^1 -> 2014 | E36: =Assumptions!$C$54*(1+Assumptions!$C$46)^2 -> 2134.84 | F36: =Assumptions!$C$54*(1+Assumptions!$C$46)^3 -> 2262.9304 | G36: =Assumptions!$C$54*(1+Assumptions!$C$46)^4 -> 2398.7062 | H36: =Assumptions!$C$54*(1+Assumptions!$C$46)^5 -> 2542.6286 | I36: =Assumptions!$C$54*(1+Assumptions!$C$46)^6 -> 2695.1863 | J36: =Assumptions!$C$54*(1+Assumptions!$C$46)^7 -> 2856.8975 | K36: =Assumptions!$C$54*(1+Assumptions!$C$46)^8 -> 3028.3113 | L36: =Assumptions!$C$54*(1+Assumptions!$C$46)^9 -> 3210.01
A37: Dialysis revenue | B37: Rs Lakh | C37: =C34*C35*C36/100000 -> 59.85 | D37: =D34*D35*D36/100000 -> 95.1615 | E37: =E34*E35*E36/100000 -> 134.49492 | F37: =F34*F35*F36/100000 -> 161.57323 | G37: =G34*G35*G36/100000 -> 188.89812 | H37: =H34*H35*H36/100000 -> 213.5808 | I37: =I34*I35*I36/100000 -> 232.05554 | J37: =J34*J35*J36/100000 -> 248.97862 | ... L37: =L34*L35*L36/100000 -> 286.49339
A39: F. Other operating income
A40: Health checks, ambulance, academics, cafeteria & retail rentals | B40: Rs Lakh | C40: =Assumptions!C$62 -> 40 | D40: =Assumptions!D$62 -> 55 | E40: =Assumptions!E$62 -> 70 | F40: =Assumptions!F$62 -> 82 | G40: =Assumptions!G$62 -> 95 | H40: =Assumptions!H$62 -> 105 | I40: =Assumptions!I$62 -> 115 | J40: =Assumptions!J$62 -> 124 | ... L40: =Assumptions!L$62 -> 142
A42: TOTAL OPERATING REVENUE
A43: Total operating revenue | B43: Rs Lakh | C43: =C15+C21+C26+C31+C37+C40 -> 3013.3215 | D43: =D15+D21+D26+D31+D37+D40 -> 5112.4055 | E43: =E15+E21+E26+E31+E37+E40 -> 7204.879 | F43: =F15+F21+F26+F31+F37+F40 -> 8880.2355 | G43: =G15+G21+G26+G31+G37+G40 -> 10439.459 | H43: =H15+H21+H26+H31+H37+H40 -> 11622.05 | I43: =I15+I21+I26+I31+I37+I40 -> 12602.74 | J43: =J15+J21+J26+J31+J37+J40 -> 13591.63 | ... L43: =L15+L21+L26+L31+L37+L40 -> 15830.817
A44: Revenue growth (YoY) | B44: % | C44: =0 -> 0 | D44: =D43/C43-1 -> 0.69660142 | E44: =E43/D43-1 -> 0.40929334 | F44: =F43/E43-1 -> 0.23253083 | G44: =G43/F43-1 -> 0.17558354 | H44: =H43/G43-1 -> 0.11328085 | I44: =I43/H43-1 -> 0.084381925 | J44: =J43/I43-1 -> 0.078466201 | K44: =K43/J43-1 -> 0.0803744 | L44: =L43/K43-1 -> 0.078096164
A45: Total operating revenue | B45: Rs Crore | C45: =C43/100 -> 30.133215 | D45: =D43/100 -> 51.124055 | E45: =E43/100 -> 72.04879 | F45: =F43/100 -> 88.802355 | G45: =G43/100 -> 104.39459 | H45: =H43/100 -> 116.2205 | I45: =I43/100 -> 126.0274 | J45: =J43/100 -> 135.9163 | ... L45: =L43/100 -> 158.30817
A47: Revenue mix
A48: Inpatient (IPD) | B48: % | C48: =C15/C43 -> 0.79831309 | D48: =D15/D43 -> 0.79867399 | E48: =E15/E43 -> 0.79199047 | F48: =F15/F43 -> 0.78818113 | G48: =G15/G43 -> 0.78552991 | H48: =H15/H43 -> 0.78197833 | I48: =I15/I43 -> 0.77521276 | J48: =J15/J43 -> 0.77272122 | ... L48: =L15/L43 -> 0.76666913
...

Sheet Manpower
A1: MANPOWER PLAN & COST
A2: Headcount ramp by cadre. Cost escalates at the salary-escalation assumption. Rs Lakh.
A4: Cadre | B4: Unit | C4: Year 1 | D4: Year 2 | E4: Year 3 | F4: Year 4 | G4: Year 5 | H4: Year 6 | I4: Year 7 | J4: Year 8 | K4: Year 9 | L4: Year 10
A5: Financial year | C5: FY2029 | D5: FY2030 | E5: FY2031 | F5: FY2032 | G5: FY2033 | H5: FY2034 | I5: FY2035 | J5: FY2036 | K5: FY2037 | L5: FY2038
A6: Full-time consultants (retainer / employed) | B6: nos | C6: 16 | D6: 18 | E6: 19 | F6: 20 | G6: 20 | H6: 20 | I6: 20 | J6: 20 | K6: 20 | L6: 20 | N6: The clinical anchors. A tier-2 hospital lives or dies on retaining these.
A7: Resident medical officers / DNB residents | B7: nos | C7: 18 | D7: 21 | E7: 23 | F7: 23 | G7: 24 | H7: 24 | I7: 24 | J7: 24 | K7: 24 | L7: 24
A8: Nursing staff | B8: nos | C8: 105 | D8: 123 | E8: 132 | F8: 136 | G8: 140 | H8: 140 | I8: 140 | J8: 140 | K8: 140 | L8: 140 | N8: Nurse:bed ratio ~1.4:1 at maturity, higher in critical care
A9: Paramedical & technicians | B9: nos | C9: 34 | D9: 40 | E9: 43 | F9: 45 | G9: 46 | H9: 46 | I9: 46 | J9: 46 | K9: 46 | L9: 46
A10: Pharmacy staff | B10: nos | C10: 9 | D10: 10 | E10: 11 | F10: 12 | G10: 12 | H10: 12 | I10: 12 | J10: 12 | K10: 12 | L10: 12
A11: Front office, admissions, billing & TPA | B11: nos | C11: 23 | D11: 27 | E11: 29 | F11: 30 | G11: 31 | H11: 31 | I11: 31 | J11: 31 | K11: 31 | L11: 31 | N11: TPA desk size scales with the insurance mix
A12: Finance, HR, IT, quality & NABH | B12: nos | C12: 11 | D12: 13 | E12: 14 | F12: 15 | G12: 15 | H12: 15 | I12: 15 | J12: 15 | K12: 15 | L12: 15
A13: In-house support (biomedical, maintenance) | B13: nos | C13: 19 | D13: 20 | E13: 21 | F13: 21 | G13: 21 | H13: 21 | I13: 21 | J13: 21 | K13: 21 | L13: 21
A14: Total headcount | B14: nos | C14: =SUM(C6:C13) -> 235 | D14: =SUM(D6:D13) -> 272 | E14: =SUM(E6:E13) -> 292 | F14: =SUM(F6:F13) -> 302 | G14: =SUM(G6:G13) -> 309 | H14: =SUM(H6:H13) -> 309 | I14: =SUM(I6:I13) -> 309 | J14: =SUM(J6:J13) -> 309 | ... L14: =SUM(L6:L13) -> 309
A15: Staff per bed | B15: ratio | C15: =C14/Assumptions!$C$5 -> 2.35 | D15: =D14/Assumptions!$C$5 -> 2.72 | E15: =E14/Assumptions!$C$5 -> 2.92 | F15: =F14/Assumptions!$C$5 -> 3.02 | G15: =G14/Assumptions!$C$5 -> 3.09 | H15: =H14/Assumptions!$C$5 -> 3.09 | I15: =I14/Assumptions!$C$5 -> 3.09 | J15: =J14/Assumptions!$C$5 -> 3.09 | ... L15: =L14/Assumptions!$C$5 -> 3.09 | N15: Indian multi-specialty hospitals run 2.5-3.5 staff per bed
A17: Cost per head (Year 1, Rs Lakh per annum)
A18: Full-time consultants (retainer / employed) | B18: Rs L p.a. | C18: 32
A19: Resident medical officers / DNB residents | B19: Rs L p.a. | C19: 9.5
A20: Nursing staff | B20: Rs L p.a. | C20: 3.9
A21: Paramedical & technicians | B21: Rs L p.a. | C21: 4.4
A22: Pharmacy staff | B22: Rs L p.a. | C22: 3.2
A23: Front office, admissions, billing & TPA | B23: Rs L p.a. | C23: 4.2
A24: Finance, HR, IT, quality & NABH | B24: Rs L p.a. | C24: 7
A25: In-house support (biomedical, maintenance) | B25: Rs L p.a. | C25: 2.6
A27: Salary cost
A28: Cost at Year-1 rates (headcount x Year-1 cost per head) | B28: Rs Lakh | C28: =C6*$C$18+C7*$C$19+C8*$C$20+C9*$C$21+C10*$C$22+C11*$C$23+C12*$C$24+C13*$C$25 -> 1493.9 | D28: =D6*$C$18+D7*$C$19+D8*$C$20+D9*$C$21+D10*$C$22+D11*$C$23+D12*$C$24+D13*$C$25 -> 1719.6 | E28: =E6*$C$18+E7*$C$19+E8*$C$20+E9*$C$21+E10*$C$22+E11*$C$23+E12*$C$24+E13*$C$25 -> 1840.1 | F28: =F6*$C$18+F7*$C$19+F8*$C$20+F9*$C$21+F10*$C$22+F11*$C$23+F12*$C$24+F13*$C$25 -> 1910.9 | G28: =G6*$C$18+G7*$C$19+G8*$C$20+G9*$C$21+G10*$C$22+G11*$C$23+G12*$C$24+G13*$C$25 -> 1944.6 | H28: =H6*$C$18+H7*$C$19+H8*$C$20+H9*$C$21+H10*$C$22+H11*$C$23+H12*$C$24+H13*$C$25 -> 1944.6 | I28: =I6*$C$18+I7*$C$19+I8*$C$20+I9*$C$21+I10*$C$22+I11*$C$23+I12*$C$24+I13*$C$25 -> 1944.6 | J28: =J6*$C$18+J7*$C$19+J8*$C$20+J9*$C$21+J10*$C$22+J11*$C$23+J12*$C$24+J13*$C$25 -> 1944.6 | ... L28: =L6*$C$18+L7*$C$19+L8*$C$20+L9*$C$21+L10*$C$22+L11*$C$23+L12*$C$24+L13*$C$25 -> 1944.6
A29: Cumulative escalation factor | B29: x | C29: =(1+Assumptions!$C$68)^0 -> 1 | D29: =(1+Assumptions!$C$68)^1 -> 1.08 | E29: =(1+Assumptions!$C$68)^2 -> 1.1664 | F29: =(1+Assumptions!$C$68)^3 -> 1.259712 | G29: =(1+Assumptions!$C$68)^4 -> 1.360489 | H29: =(1+Assumptions!$C$68)^5 -> 1.4693281 | I29: =(1+Assumptions!$C$68)^6 -> 1.5868743 | J29: =(1+Assumptions!$C$68)^7 -> 1.7138243 | K29: =(1+Assumptions!$C$68)^8 -> 1.8509302 | L29: =(1+Assumptions!$C$68)^9 -> 1.9990046
A30: TOTAL SALARY & WAGE COST | B30: Rs Lakh | C30: =C28*C29 -> 1493.9 | D30: =D28*D29 -> 1857.168 | E30: =E28*E29 -> 2146.2926 | F30: =F28*F29 -> 2407.1837 | G30: =G28*G29 -> 2645.6068 | H30: =H28*H29 -> 2857.2554 | I30: =I28*I29 -> 3085.8358 | J30: =J28*J29 -> 3332.7027 | ... L30: =L28*L29 -> 3887.2644
A31: Average cost per employee | B31: Rs Lakh | C31: =C30/C14 -> 6.3570213 | D31: =D30/D14 -> 6.8278235 | E31: =E30/E14 -> 7.3503173 | F31: =F30/F14 -> 7.9708068 | G31: =G30/G14 -> 8.5618344 | H31: =H30/H14 -> 9.2467812 | I31: =I30/I14 -> 9.9865237 | J31: =J30/J14 -> 10.785446 | ... L31: =L30/L14 -> 12.580144
A32: Salary cost as % of revenue | B32: % | C32: =C30/'Revenue Build'!C$43 -> 0.49576523 | D32: =D30/'Revenue Build'!D$43 -> 0.36326696 | E32: =E30/'Revenue Build'!E$43 -> 0.29789434 | F32: =F30/'Revenue Build'!F$43 -> 0.27107205 | G32: =G30/'Revenue Build'!G$43 -> 0.25342375 | H32: =H30/'Revenue Build'!H$43 -> 0.24584781 | I32: =I30/'Revenue Build'!I$43 -> 0.24485435 | J32: =J30/'Revenue Build'!J$43 -> 0.24520258 | ... L32: =L30/'Revenue Build'!L$43 -> 0.24555047 | N32: Indian hospitals typically run 22-28% at maturity; higher in the ramp years

Sheet Operating Costs
A1: OPERATING COST BUILD-UP
A2: Classified into variable (scales with revenue) and fixed / semi-fixed. Rs Lakh.
A4: Cost head | B4: Basis | C4: Year 1 | D4: Year 2 | E4: Year 3 | F4: Year 4 | G4: Year 5 | H4: Year 6 | I4: Year 7 | J4: Year 8 | K4: Year 9 | L4: Year 10
A5: Financial year | C5: FY2029 | D5: FY2030 | E5: FY2031 | F5: FY2032 | G5: FY2033 | H5: FY2034 | I5: FY2035 | J5: FY2036 | K5: FY2037 | L5: FY2038
A6: Variable costs
A7: Consultant payout — fee-for-service | B7: % of IPD+OPD | C7: =Assumptions!$C$65*('Revenue Build'!C$15+'Revenue Build'!C$21) -> 292.71814 | D7: =Assumptions!$C$65*('Revenue Build'!D$15+'Revenue Build'!D$21) -> 496.81206 | E7: =Assumptions!$C$65*('Revenue Build'!E$15+'Revenue Build'!E$21) -> 697.15482 | F7: =Assumptions!$C$65*('Revenue Build'!F$15+'Revenue Build'!F$21) -> 856.94686 | G7: =Assumptions!$C$65*('Revenue Build'!G$15+'Revenue Build'!G$21) -> 1004.9533 | H7: =Assumptions!$C$65*('Revenue Build'!H$15+'Revenue Build'!H$21) -> 1116.2946 | I7: =Assumptions!$C$65*('Revenue Build'!I$15+'Revenue Build'!I$21) -> 1204.2479 | J7: =Assumptions!$C$65*('Revenue Build'!J$15+'Revenue Build'!J$21) -> 1296.8489 | ... L7: =Assumptions!$C$65*('Revenue Build'!L$15+'Revenue Build'!L$21) -> 1503.6338
A8: Consumables — drugs, implants, disposables, reagents | B8: % of revenue | C8: =Assumptions!$C$66*'Revenue Build'!C$43 -> 693.06394 | D8: =Assumptions!$C$66*'Revenue Build'!D$43 -> 1175.8533 | E8: =Assumptions!$C$66*'Revenue Build'!E$43 -> 1657.1222 | F8: =Assumptions!$C$66*'Revenue Build'!F$43 -> 2042.4542 | G8: =Assumptions!$C$66*'Revenue Build'!G$43 -> 2401.0755 | H8: =Assumptions!$C$66*'Revenue Build'!H$43 -> 2673.0714 | I8: =Assumptions!$C$66*'Revenue Build'!I$43 -> 2898.6303 | J8: =Assumptions!$C$66*'Revenue Build'!J$43 -> 3126.0748 | ... L8: =Assumptions!$C$66*'Revenue Build'!L$43 -> 3641.0878
A9: Total variable costs | B9: Rs Lakh | C9: =C7+C8 -> 985.78207 | D9: =D7+D8 -> 1672.6653 | E9: =E7+E8 -> 2354.277 | F9: =F7+F8 -> 2899.401 | G9: =G7+G8 -> 3406.0288 | H9: =H7+H8 -> 3789.366 | I9: =I7+I8 -> 4102.8782 | J9: =J7+J8 -> 4422.9237 | ... L9: =L7+L8 -> 5144.7216
A11: Fixed & semi-fixed costs
A12: Salaries & wages | B12: Rs Lakh | C12: =Manpower!C$30 -> 1493.9 | D12: =Manpower!D$30 -> 1857.168 | E12: =Manpower!E$30 -> 2146.2926 | F12: =Manpower!F$30 -> 2407.1837 | G12: =Manpower!G$30 -> 2645.6068 | H12: =Manpower!H$30 -> 2857.2554 | I12: =Manpower!I$30 -> 3085.8358 | J12: =Manpower!J$30 -> 3332.7027 | ... L12: =Manpower!L$30 -> 3887.2644
A13: Power & fuel | B13: Rs Lakh | C13: =Assumptions!C$72 -> 200 | D13: =Assumptions!D$72 -> 250 | E13: =Assumptions!E$72 -> 310 | F13: =Assumptions!F$72 -> 380 | G13: =Assumptions!G$72 -> 460 | H13: =Assumptions!H$72 -> 500 | I13: =Assumptions!I$72 -> 530 | J13: =Assumptions!J$72 -> 560 | ... L13: =Assumptions!L$72 -> 620
A14: Outsourced services | B14: Rs Lakh | C14: =Assumptions!C$73 -> 185 | D14: =Assumptions!D$73 -> 215 | E14: =Assumptions!E$73 -> 265 | F14: =Assumptions!F$73 -> 300 | G14: =Assumptions!G$73 -> 420 | H14: =Assumptions!H$73 -> 445 | I14: =Assumptions!I$73 -> 470 | J14: =Assumptions!J$73 -> 495 | ... L14: =Assumptions!L$73 -> 545
A15: Repairs & maintenance | B15: Rs Lakh | C15: =Assumptions!C$74 -> 120 | D15: =Assumptions!D$74 -> 145 | E15: =Assumptions!E$74 -> 190 | F15: =Assumptions!F$74 -> 240 | G15: =Assumptions!G$74 -> 300 | H15: =Assumptions!H$74 -> 330 | I15: =Assumptions!I$74 -> 355 | J15: =Assumptions!J$74 -> 380 | ... L15: =Assumptions!L$74 -> 430
A16: Administrative & other overheads | B16: Rs Lakh | C16: =Assumptions!C$75 -> 155 | D16: =Assumptions!D$75 -> 180 | E16: =Assumptions!E$75 -> 230 | F16: =Assumptions!F$75 -> 300 | G16: =Assumptions!G$75 -> 380 | H16: =Assumptions!H$75 -> 410 | I16: =Assumptions!I$75 -> 440 | J16: =Assumptions!J$75 -> 470 | ... L16: =Assumptions!L$75 -> 530
A17: Marketing & business development | B17: Rs Lakh | C17: =Assumptions!C$76 -> 170 | D17: =Assumptions!D$76 -> 175 | E17: =Assumptions!E$76 -> 180 | F17: =Assumptions!F$76 -> 185 | G17: =Assumptions!G$76 -> 190 | H17: =Assumptions!H$76 -> 200 | I17: =Assumptions!I$76 -> 210 | J17: =Assumptions!J$76 -> 220 | ... L17: =Assumptions!L$76 -> 240
A18: Insurance, rates & taxes, licences | B18: Rs Lakh | C18: =Assumptions!C$77 -> 90 | D18: =Assumptions!D$77 -> 100 | E18: =Assumptions!E$77 -> 120 | F18: =Assumptions!F$77 -> 140 | G18: =Assumptions!G$77 -> 160 | H18: =Assumptions!H$77 -> 172 | I18: =Assumptions!I$77 -> 184 | J18: =Assumptions!J$77 -> 196 | ... L18: =Assumptions!L$77 -> 220
A19: Total fixed & semi-fixed costs | B19: Rs Lakh | C19: =SUM(C12:C18) -> 2413.9 | D19: =SUM(D12:D18) -> 2922.168 | E19: =SUM(E12:E18) -> 3441.2926 | F19: =SUM(F12:F18) -> 3952.1837 | G19: =SUM(G12:G18) -> 4555.6068 | H19: =SUM(H12:H18) -> 4914.2554 | I19: =SUM(I12:I18) -> 5274.8358 | J19: =SUM(J12:J18) -> 5653.7027 | ... L19: =SUM(L12:L18) -> 6472.2644
A21: TOTAL OPERATING EXPENDITURE
A22: Total operating expenditure | B22: Rs Lakh | C22: =C9+C19 -> 3399.6821 | D22: =D9+D19 -> 4594.8333 | E22: =E9+E19 -> 5795.5696 | F22: =F9+F19 -> 6851.5847 | G22: =G9+G19 -> 7961.6357 | H22: =H9+H19 -> 8703.6213 | I22: =I9+I19 -> 9377.714 | J22: =J9+J19 -> 10076.626 | ... L22: =L9+L19 -> 11616.986
A23: Operating expenditure as % of revenue | B23: % | C23: =C22/'Revenue Build'!C$43 -> 1.1282175 | D23: =D22/'Revenue Build'!D$43 -> 0.89876152 | E23: =E22/'Revenue Build'!E$43 -> 0.80439514 | F23: =F22/'Revenue Build'!F$43 -> 0.77155439 | G23: =G22/'Revenue Build'!G$43 -> 0.76264832 | H23: =H22/'Revenue Build'!H$43 -> 0.74888868 | I23: =I22/'Revenue Build'!I$43 -> 0.74410118 | J23: =J22/'Revenue Build'!J$43 -> 0.74138471 | ... L23: =L22/'Revenue Build'!L$43 -> 0.73382102
A25: EBITDA
A26: EBITDA | B26: Rs Lakh | C26: ='Revenue Build'!C$43-C22 -> -386.36061 | D26: ='Revenue Build'!D$43-D22 -> 517.57216 | E26: ='Revenue Build'!E$43-E22 -> 1409.3094 | F26: ='Revenue Build'!F$43-F22 -> 2028.6508 | G26: ='Revenue Build'!G$43-G22 -> 2477.8231 | H26: ='Revenue Build'!H$43-H22 -> 2918.4282 | I26: ='Revenue Build'!I$43-I22 -> 3225.0265 | J26: ='Revenue Build'!J$43-J22 -> 3515.0033 | ... L26: ='Revenue Build'!L$43-L22 -> 4213.8306
A27: EBITDA margin | B27: % | C27: =C26/'Revenue Build'!C$43 -> -0.12821752 | D27: =D26/'Revenue Build'!D$43 -> 0.10123848 | E27: =E26/'Revenue Build'!E$43 -> 0.19560486 | F27: =F26/'Revenue Build'!F$43 -> 0.22844561 | G27: =G26/'Revenue Build'!G$43 -> 0.23735168 | H27: =H26/'Revenue Build'!H$43 -> 0.25111132 | I27: =I26/'Revenue Build'!I$43 -> 0.25589882 | J27: =J26/'Revenue Build'!J$43 -> 0.25861529 | ... L27: =L26/'Revenue Build'!L$43 -> 0.26617898 | N27: ICRA: sector operating margin 22-24%. A well-run tier-2 asset reaches 25-27% at maturity.
A28: EBITDA per operational bed | B28: Rs Lakh | C28: =C26/Assumptions!$C$5 -> -3.8636061 | D28: =D26/Assumptions!$C$5 -> 5.1757216 | E28: =E26/Assumptions!$C$5 -> 14.093094 | F28: =F26/Assumptions!$C$5 -> 20.286508 | G28: =G26/Assumptions!$C$5 -> 24.778231 | H28: =H26/Assumptions!$C$5 -> 29.184282 | I28: =I26/Assumptions!$C$5 -> 32.250265 | J28: =J26/Assumptions!$C$5 -> 35.150033 | ... L28: =L26/Assumptions!$C$5 -> 42.138306
A30: Cost structure analysis
A31: Variable costs as % of revenue | B31: % | C31: =C9/'Revenue Build'!C$43 -> 0.32714136 | D31: =D9/'Revenue Build'!D$43 -> 0.32717775 | E31: =E9/'Revenue Build'!E$43 -> 0.32676149 | F31: =F9/'Revenue Build'!F$43 -> 0.32650047 | G31: =G9/'Revenue Build'!G$43 -> 0.32626489 | H31: =H9/'Revenue Build'!H$43 -> 0.32604972 | I31: =I9/'Revenue Build'!I$43 -> 0.32555445 | J31: =J9/'Revenue Build'!J$43 -> 0.32541526 | ... L31: =L9/'Revenue Build'!L$43 -> 0.32498144
A32: Fixed costs as % of revenue | B32: % | C32: =C19/'Revenue Build'!C$43 -> 0.80107616 | D32: =D19/'Revenue Build'!D$43 -> 0.57158377 | E32: =E19/'Revenue Build'!E$43 -> 0.47763365 | F32: =F19/'Revenue Build'!F$43 -> 0.44505392 | G32: =G19/'Revenue Build'!G$43 -> 0.43638343 | H32: =H19/'Revenue Build'!H$43 -> 0.42283896 | I32: =I19/'Revenue Build'!I$43 -> 0.41854673 | J32: =J19/'Revenue Build'!J$43 -> 0.41596945 | ... L32: =L19/'Revenue Build'!L$43 -> 0.40883958 | N32: Falls sharply as occupancy ramps — this is the operating leverage that makes hospitals attractive
A33: Contribution margin ratio | B33: % | C33: =1-C31 -> 0.67285864 | D33: =1-D31 -> 0.67282225 | E33: =1-E31 -> 0.67323851 | F33: =1-F31 -> 0.67349953 | G33: =1-G31 -> 0.67373511 | H33: =1-H31 -> 0.67395028 | I33: =1-I31 -> 0.67444555 | J33: =1-J31 -> 0.67458474 | ... L33: =1-L31 -> 0.67501856

Sheet Working Capital
A1: WORKING CAPITAL
A2: Receivables are driven by the payer mix — the single largest working-capital lever in an Indian hospital. Rs Lakh.
A4: Particulars | B4: Basis | C4: Year 1 | D4: Year 2 | E4: Year 3 | F4: Year 4 | G4: Year 5 | H4: Year 6 | I4: Year 7 | J4: Year 8 | K4: Year 9 | L4: Year 10
A5: Financial year | C5: FY2029 | D5: FY2030 | E5: FY2031 | F5: FY2032 | G5: FY2033 | H5: FY2034 | I5: FY2035 | J5: FY2036 | K5: FY2037 | L5: FY2038
A6: Current assets
A7: Debtor days (weighted by payer mix) | B7: days | C7: =Assumptions!$C$80 -> 47.95 | D7: =Assumptions!$C$80 -> 47.95 | E7: =Assumptions!$C$80 -> 47.95 | F7: =Assumptions!$C$80 -> 47.95 | G7: =Assumptions!$C$80 -> 47.95 | H7: =Assumptions!$C$80 -> 47.95 | I7: =Assumptions!$C$80 -> 47.95 | J7: =Assumptions!$C$80 -> 47.95 | ... L7: =Assumptions!$C$80 -> 47.95
A8: Trade receivables | B8: Rs Lakh | C8: ='Revenue Build'!C$43*C7/365 -> 395.85963 | D8: ='Revenue Build'!D$43*D7/365 -> 671.61601 | E8: ='Revenue Build'!E$43*E7/365 -> 946.50397 | F8: ='Revenue Build'!F$43*F7/365 -> 1166.5953 | G8: ='Revenue Build'!G$43*G7/365 -> 1371.4303 | H8: ='Revenue Build'!H$43*H7/365 -> 1526.7871 | I8: ='Revenue Build'!I$43*I7/365 -> 1655.6203 | J8: ='Revenue Build'!J$43*J7/365 -> 1785.5305 | ... L8: ='Revenue Build'!L$43*L7/365 -> 2079.6922
A9: Inventory (pharmacy, implants, reagents) | B9: Rs Lakh | C9: ='Operating Costs'!C$8*Assumptions!$C$81/365 -> 47.470133 | D9: ='Operating Costs'!D$8*Assumptions!$C$81/365 -> 80.537895 | E9: ='Operating Costs'!E$8*Assumptions!$C$81/365 -> 113.50152 | F9: ='Operating Costs'!F$8*Assumptions!$C$81/365 -> 139.89412 | G9: ='Operating Costs'!G$8*Assumptions!$C$81/365 -> 164.45723 | H9: ='Operating Costs'!H$8*Assumptions!$C$81/365 -> 183.08708 | I9: ='Operating Costs'!I$8*Assumptions!$C$81/365 -> 198.53632 | J9: ='Operating Costs'!J$8*Assumptions!$C$81/365 -> 214.11471 | ... L9: ='Operating Costs'!L$8*Assumptions!$C$81/365 -> 249.38958
A10: Other current assets (advances, deposits, prepaid) | B10: Rs Lakh | C10: ='Revenue Build'!C$43*Assumptions!$C$83/365 -> 99.068103 | D10: ='Revenue Build'!D$43*Assumptions!$C$83/365 -> 168.07908 | E10: ='Revenue Build'!E$43*Assumptions!$C$83/365 -> 236.87273 | F10: ='Revenue Build'!F$43*Assumptions!$C$83/365 -> 291.95295 | G10: ='Revenue Build'!G$43*Assumptions!$C$83/365 -> 343.21508 | H10: ='Revenue Build'!H$43*Assumptions!$C$83/365 -> 382.09478 | I10: ='Revenue Build'!I$43*Assumptions!$C$83/365 -> 414.33667 | J10: ='Revenue Build'!J$43*Assumptions!$C$83/365 -> 446.8481 | ... L10: ='Revenue Build'!L$43*Assumptions!$C$83/365 -> 520.4652
A11: Total current assets (excl. cash) | B11: Rs Lakh | C11: =C8+C9+C10 -> 542.39786 | D11: =D8+D9+D10 -> 920.23299 | E11: =E8+E9+E10 -> 1296.8782 | F11: =F8+F9+F10 -> 1598.4424 | G11: =G8+G9+G10 -> 1879.1026 | H11: =H8+H9+H10 -> 2091.9689 | I11: =I8+I9+I10 -> 2268.4933 | J11: =J8+J9+J10 -> 2446.4933 | ... L11: =L8+L9+L10 -> 2849.547
A13: Current liabilities
A14: Trade payables | B14: Rs Lakh | C14: =('Operating Costs'!C$8+'Operating Costs'!C$14)*Assumptions!$C$82/365 -> 108.25446 | D14: =('Operating Costs'!D$8+'Operating Costs'!D$14)*Assumptions!$C$82/365 -> 171.47506 | E14: =('Operating Costs'!E$8+'Operating Costs'!E$14)*Assumptions!$C$82/365 -> 236.97397 | F14: =('Operating Costs'!F$8+'Operating Costs'!F$14)*Assumptions!$C$82/365 -> 288.79572 | G14: =('Operating Costs'!G$8+'Operating Costs'!G$14)*Assumptions!$C$82/365 -> 347.80383 | H14: =('Operating Costs'!H$8+'Operating Costs'!H$14)*Assumptions!$C$82/365 -> 384.41976 | I14: =('Operating Costs'!I$8+'Operating Costs'!I$14)*Assumptions!$C$82/365 -> 415.31059 | J14: =('Operating Costs'!J$8+'Operating Costs'!J$14)*Assumptions!$C$82/365 -> 446.43388 | ... L14: =('Operating Costs'!L$8+'Operating Costs'!L$14)*Assumptions!$C$82/365 -> 516.09302
A15: Other current liabilities (statutory dues, provisions, accruals) | B15: Rs Lakh | C15: ='Revenue Build'!C$43*Assumptions!$C$84/365 -> 148.60215 | D15: ='Revenue Build'!D$43*Assumptions!$C$84/365 -> 252.11863 | E15: ='Revenue Build'!E$43*Assumptions!$C$84/365 -> 355.3091 | F15: ='Revenue Build'!F$43*Assumptions!$C$84/365 -> 437.92942 | G15: ='Revenue Build'!G$43*Assumptions!$C$84/365 -> 514.82262 | H15: ='Revenue Build'!H$43*Assumptions!$C$84/365 -> 573.14217 | I15: ='Revenue Build'!I$43*Assumptions!$C$84/365 -> 621.50501 | J15: ='Revenue Build'!J$43*Assumptions!$C$84/365 -> 670.27215 | ... L15: ='Revenue Build'!L$43*Assumptions!$C$84/365 -> 780.6978
A16: Total current liabilities (excl. borrowings) | B16: Rs Lakh | C16: =C14+C15 -> 256.85661 | D16: =D14+D15 -> 423.59369 | E16: =E14+E15 -> 592.28307 | F16: =F14+F15 -> 726.72514 | G16: =G14+G15 -> 862.62645 | H16: =H14+H15 -> 957.56193 | I16: =I14+I15 -> 1036.8156 | J16: =J14+J15 -> 1116.706 | ... L16: =L14+L15 -> 1296.7908
A18: NET WORKING CAPITAL
A19: Net working capital | B19: Rs Lakh | C19: =C11-C16 -> 285.54125 | D19: =D11-D16 -> 496.6393 | E19: =E11-E16 -> 704.59515 | F19: =F11-F16 -> 871.71725 | G19: =G11-G16 -> 1016.4761 | H19: =H11-H16 -> 1134.407 | I19: =I11-I16 -> 1231.6777 | J19: =J11-J16 -> 1329.7873 | ... L19: =L11-L16 -> 1552.7562
A20: (Increase) / decrease in net working capital | B20: Rs Lakh | C20: =C19 -> 285.54125 | D20: =D19-C19 -> 211.09805 | E20: =E19-D19 -> 207.95585 | F20: =F19-E19 -> 167.1221 | G20: =G19-F19 -> 144.75887 | H20: =H19-G19 -> 117.93087 | I20: =I19-H19 -> 97.270701 | J20: =J19-I19 -> 98.109618 | K20: =K19-J19 -> 108.70371 | L20: =L19-K19 -> 114.26515 | N20: A cash OUTFLOW when positive — growth consumes working capital
A21: Net working capital in days of revenue | B21: days | C21: =C19/'Revenue Build'!C$43*365 -> 34.587268 | D21: =D19/'Revenue Build'!D$43*365 -> 35.457544 | E21: =E19/'Revenue Build'!E$43*365 -> 35.694872 | F21: =F19/'Revenue Build'!F$43*365 -> 35.82977 | G21: =G19/'Revenue Build'!G$43*365 -> 35.539561 | H21: =H19/'Revenue Build'!H$43*365 -> 35.626982 | I21: =I19/'Revenue Build'!I$43*365 -> 35.671794 | J21: =J19/'Revenue Build'!J$43*365 -> 35.711124 | ... L21: =L19/'Revenue Build'!L$43*365 -> 35.800806
A22: Cash conversion cycle | B22: days | C22: =C7+Assumptions!$C$81-Assumptions!$C$82 -> 27.95 | D22: =D7+Assumptions!$C$81-Assumptions!$C$82 -> 27.95 | E22: =E7+Assumptions!$C$81-Assumptions!$C$82 -> 27.95 | F22: =F7+Assumptions!$C$81-Assumptions!$C$82 -> 27.95 | G22: =G7+Assumptions!$C$81-Assumptions!$C$82 -> 27.95 | H22: =H7+Assumptions!$C$81-Assumptions!$C$82 -> 27.95 | I22: =I7+Assumptions!$C$81-Assumptions!$C$82 -> 27.95 | J22: =J7+Assumptions!$C$81-Assumptions!$C$82 -> 27.95 | ... L22: =L7+Assumptions!$C$81-Assumptions!$C$82 -> 27.95 | N22: Debtor days + inventory days - creditor days
A24: Why this matters: switch the Control Panel payer mix to 'Government-heavy' and watch debtor days jump from 48 to 64.
A25: On roughly Rs 100 Cr of mature revenue that is about Rs 4.5 Cr of additional permanent working capital — funded by debt,
A26: at 11.5%. Government schemes look like free volume until you price the receivable.

Sheet Repayment Schedule
A1: TERM LOAN — QUARTERLY REPAYMENT SCHEDULE
